Workbook

Sheet Admin
A1: TMS Staff Tools
A2: Last Updated: | B2: 46231
A4: Departments:
A5: id | B5: name | C5: color
A6: executive | B6: Executive | C6: exec
A7: events | B7: Events, Programming, and Sales | C7: yellow
A8: member-services | B8: Member Services and Recognition | C8: green
A9: content | B9: Content | C9: orange
A10: marketing | B10: Marketing and Communications | C10: blue
A11: finance | B11: Finance | C11: pink
A13: Meta:
A14: organization | B14: The Minerals, Metals & Materials Society
A15: shortName | B15: TMS
A16: address | B16: 5700 Corporate Drive Suite 750, Pittsburgh, PA 15237 USA
A17: phone | B17: 1-724-776-9000
A18: fax | B18: 1-724-776-3770
A19: website | B19: www.tms.org
A20: version | B20: v0.35

Sheet Arbuckle, A
A1: First Name: | C1: Alicia
A2: Last Name: | C2: Arbuckle
A3: Title: | C3: Controller and Department Head, Finance
A4: Birthdate: | C4: November 24
A5: Id: | C5: Arbuckle-Alicia
A6: Direct: | C6: 724-814-3146
A7: Ext: | C7: 235
A8: Mobile: | C8: 724-495-9548
A9: Email: | C9: aarbuckle@tms.org
A10: Photo: | C10: ArbuckleAlicia.jpg
A11: Dept ID: | C11: finance
A12: Role: | C12: dept_head
A13: Reporting: | C13: Dunlap-Trudi
A14: Description: | C14: Short Descriptions can be added to all staff or leave blank…
A16: Work Schedule
A17: Instructions: | C17: =FormTools!B1 -> 1. MARK YOUR SCHEDULE: Use dropdown menus or begin typing to select start/end times for each day's work blocks. Leave unused blocks empty. Include location designations for each work block (Office, Remote) 2. CORE HOURS REQUIREMENT: You must routinely schedule at least 7 working hours between 7:00 AM - 5:00 PM, Monday through Thursday, unless using PTO or Travel. 3. DAILY LIMIT: Maximum 10 hours per day. Note: Non-Exempt employees are limited to 40 hours per week and all employees are limited to 75 hours per pay period, unless overtime has been approved by your supervisor. Green = Compliant, Red = Non-Compliant. Form auto-calculates totals and compliance.
C20: WEEK 1 (Pay Week)
C21: Saturday | F21: Sunday | I21: Monday | L21: Tuesday | O21: Wednesday | R21: Thursday | U21: Friday
C22: Start | D22: End | E22: Location | F22: Start | G22: End | H22: Location | I22: Start | J22: End | K22: Location | L22: Start | M22: End | N22: Location | O22: Start | P22: End | Q22: Location | R22: Start | S22: End | T22: Location | U22: Start | V22: End | W22: Location
A23: Work Block 1 | I23: 0.29166667 | J23: 0.47916667 | K23: Remote | L23: 0.34375 | M23: 0.5 | N23: Office | O23: 0.29166667 | P23: 0.47916667 | Q23: Remote | R23: 0.34375 | S23: 0.5 | T23: Office
A24: Work Block 2 | I24: 0.5 | J24: 0.6875 | K24: Remote | L24: 0.51041667 | M24: 0.70833333 | N24: Office | O24: 0.5 | P24: 0.6875 | Q24: Remote | R24: 0.51041667 | S24: 0.70833333 | T24: Office
A25: Work Block 3
A26: Work Block 4
A27: Work Block 5
A29: Total HRS/Day | C29: {=SUM((D23:D27-C23:C27)*24)} -> 0 | F29: {=SUM((G23:G27-F23:F27)*24)} -> 0 | I29: {=SUM((J23:J27-I23:I27)*24)} -> 9 | L29: {=SUM((M23:M27-L23:L27)*24)} -> 8.5 | O29: {=SUM((P23:P27-O23:O27)*24)} -> 9 | R29: {=SUM((S23:S27-R23:R27)*24)} -> 8.5 | U29: {=SUM((V23:V27-U23:U27)*24)} -> 0
A30: Total HRS/Day <=10? | C30: =C29<=10 -> TRUE | F30: =F29<=10 -> TRUE | I30: =I29<=10 -> TRUE | L30: =L29<=10 -> TRUE | O30: =O29<=10 -> TRUE | R30: =R29<=10 -> TRUE | U30: =U29<=10 -> TRUE
A31: Core Hours = 7 of 10? | C31: N/A | F31: N/A | I31: =IF(J23<>"",MAX(0,(MIN(TIME(17,0,0),J23)-MAX(TIME(7,0,0),I23))*24),0) + IF(J24<>"",MAX(0,(MIN(TIME(17,0,0),J24)-MAX(TIME(7,0,0),I24))*24),0) + IF(J25<>"",MAX(0,(MIN(TIME(17,0,0),J25)-MAX(TIME(7,0,0),I25))*24),0) + IF(J26<>"",MAX(0,(MIN(TIME(17,0,0),J26)-MAX(TIME(7,0,0),I26))*24),0) + IF(J27<>"",MAX(0,(MIN(TIME(17,0,0),J27)-MAX(TIME(7,0,0),I27))*24),0) >= 7 -> TRUE | L31: =IF(M23<>"",MAX(0,(MIN(TIME(17,0,0),M23)-MAX(TIME(7,0,0),L23))*24),0) + IF(M24<>"",MAX(0,(MIN(TIME(17,0,0),M24)-MAX(TIME(7,0,0),L24))*24),0) + IF(M25<>"",MAX(0,(MIN(TIME(17,0,0),M25)-MAX(TIME(7,0,0),L25))*24),0) + IF(M26<>"",MAX(0,(MIN(TIME(17,0,0),M26)-MAX(TIME(7,0,0),L26))*24),0) + IF(M27<>"",MAX(0,(MIN(TIME(17,0,0),M27)-MAX(TIME(7,0,0),L27))*24),0) >= 7 -> TRUE | O31: =IF(P23<>"",MAX(0,(MIN(TIME(17,0,0),P23)-MAX(TIME(7,0,0),O23))*24),0) + IF(P24<>"",MAX(0,(MIN(TIME(17,0,0),P24)-MAX(TIME(7,0,0),O24))*24),0) + IF(P25<>"",MAX(0,(MIN(TIME(17,0,0),P25)-MAX(TIME(7,0,0),O25))*24),0) + IF(P26<>"",MAX(0,(MIN(TIME(17,0,0),P26)-MAX(TIME(7,0,0),O26))*24),0) + IF(P27<>"",MAX(0,(MIN(TIME(17,0,0),P27)-MAX(TIME(7,0,0),O27))*24),0) >= 7 -> TRUE | R31: =IF(S23<>"",MAX(0,(MIN(TIME(17,0,0),S23)-MAX(TIME(7,0,0),R23))*24),0) + IF(S24<>"",MAX(0,(MIN(TIME(17,0,0),S24)-MAX(TIME(7,0,0),R24))*24),0) + IF(S25<>"",MAX(0,(MIN(TIME(17,0,0),S25)-MAX(TIME(7,0,0),R25))*24),0) + IF(S26<>"",MAX(0,(MIN(TIME(17,0,0),S26)-MAX(TIME(7,0,0),R26))*24),0) + IF(S27<>"",MAX(0,(MIN(TIME(17,0,0),S27)-MAX(TIME(7,0,0),R27))*24),0) >= 7 -> TRUE | U31: N/A
A33: Total Hours (Week 1) | C33: =SUM(C29:W29) -> 35
C35: WEEK 2
C36: Saturday | F36: Sunday | I36: Monday | L36: Tuesday | O36: Wednesday | R36: Thursday | U36: Friday
C37: Start | D37: End | E37: Location | F37: Start | G37: End | H37: Location | I37: Start | J37: End | K37: Location | L37: Start | M37: End | N37: Location | O37: Start | P37: End | Q37: Location | R37: Start | S37: End | T37: Location | U37: Start | V37: End | W37: Location
A38: Work Block 1 | I38: 0.29166667 | J38: 0.47916667 | K38: Remote | L38: 0.34375 | M38: 0.5 | N38: Office | O38: 0.29166667 | P38: 0.47916667 | Q38: Remote | R38: 0.34375 | S38: 0.5 | T38: Office | U38: 0.29166667 | V38: 0.5 | W38: Remote
A39: Work Block 2 | I39: 0.5 | J39: 0.6875 | K39: Remote | L39: 0.51041667 | M39: 0.70833333 | N39: Office | O39: 0.5 | P39: 0.6875 | Q39: Remote | R39: 0.51041667 | S39: 0.70833333 | T39: Office
A40: Work Block 3
A41: Work Block 4
A42: Work Block 5
A44: Total HRS/Day | C44: {=SUM((D38:D42-C38:C42)*24)} -> 0 | F44: {=SUM((G38:G42-F38:F42)*24)} -> 0 | I44: {=SUM((J38:J42-I38:I42)*24)} -> 9 | L44: {=SUM((M38:M42-L38:L42)*24)} -> 8.5 | O44: {=SUM((P38:P42-O38:O42)*24)} -> 9 | R44: {=SUM((S38:S42-R38:R42)*24)} -> 8.5 | U44: {=SUM((V38:V42-U38:U42)*24)} -> 5
A45: Total HRS/Day <=10? | C45: =C44<=10 -> TRUE | F45: =F44<=10 -> TRUE | I45: =I44<=10 -> TRUE | L45: =L44<=10 -> TRUE | O45: =O44<=10 -> TRUE | R45: =R44<=10 -> TRUE | U45: =U44<=10 -> TRUE
A46: Core Hours = 7 of 10? | C46: N/A | F46: N/A | I46: =IF(J38<>"",MAX(0,(MIN(TIME(17,0,0),J38)-MAX(TIME(7,0,0),I38))*24),0) + IF(J39<>"",MAX(0,(MIN(TIME(17,0,0),J39)-MAX(TIME(7,0,0),I39))*24),0) + IF(J40<>"",MAX(0,(MIN(TIME(17,0,0),J40)-MAX(TIME(7,0,0),I40))*24),0) + IF(J41<>"",MAX(0,(MIN(TIME(17,0,0),J41)-MAX(TIME(7,0,0),I41))*24),0) + IF(J42<>"",MAX(0,(MIN(TIME(17,0,0),J42)-MAX(TIME(7,0,0),I42))*24),0) >= 7 -> TRUE | L46: =IF(M38<>"",MAX(0,(MIN(TIME(17,0,0),M38)-MAX(TIME(7,0,0),L38))*24),0) + IF(M39<>"",MAX(0,(MIN(TIME(17,0,0),M39)-MAX(TIME(7,0,0),L39))*24),0) + IF(M40<>"",MAX(0,(MIN(TIME(17,0,0),M40)-MAX(TIME(7,0,0),L40))*24),0) + IF(M41<>"",MAX(0,(MIN(TIME(17,0,0),M41)-MAX(TIME(7,0,0),L41))*24),0) + IF(M42<>"",MAX(0,(MIN(TIME(17,0,0),M42)-MAX(TIME(7,0,0),L42))*24),0) >= 7 -> TRUE | O46: =IF(P38<>"",MAX(0,(MIN(TIME(17,0,0),P38)-MAX(TIME(7,0,0),O38))*24),0) + IF(P39<>"",MAX(0,(MIN(TIME(17,0,0),P39)-MAX(TIME(7,0,0),O39))*24),0) + IF(P40<>"",MAX(0,(MIN(TIME(17,0,0),P40)-MAX(TIME(7,0,0),O40))*24),0) + IF(P41<>"",MAX(0,(MIN(TIME(17,0,0),P41)-MAX(TIME(7,0,0),O41))*24),0) + IF(P42<>"",MAX(0,(MIN(TIME(17,0,0),P42)-MAX(TIME(7,0,0),O42))*24),0) >= 7 -> TRUE | R46: =IF(S38<>"",MAX(0,(MIN(TIME(17,0,0),S38)-MAX(TIME(7,0,0),R38))*24),0) + IF(S39<>"",MAX(0,(MIN(TIME(17,0,0),S39)-MAX(TIME(7,0,0),R39))*24),0) + IF(S40<>"",MAX(0,(MIN(TIME(17,0,0),S40)-MAX(TIME(7,0,0),R40))*24),0) + IF(S41<>"",MAX(0,(MIN(TIME(17,0,0),S41)-MAX(TIME(7,0,0),R41))*24),0) + IF(S42<>"",MAX(0,(MIN(TIME(17,0,0),S42)-MAX(TIME(7,0,0),R42))*24),0) >= 7 -> TRUE | U46: N/A
A48: Total Hours (Week 2) | C48: =SUM(C44:W44) -> 40
...

Sheet Baker, M
A1: First Name: | C1: Matt
A2: Last Name: | C2: Baker
A3: Title: | C3: Department Head, Content
A4: Birthdate: | C4: December 4
A5: Id: | C5: Baker-Matt
A6: Direct: | C6: 724-814-3176
A7: Ext: | C7: 280
A8: Mobile: | C8: 717-575-8007
A9: Email: | C9: mbaker@tms.org
A10: Photo: | C10: BakerMatt.jpg
A11: Dept ID: | C11: content
A12: Role: | C12: dept_head
A13: Reporting: | C13: Dunlap-Trudi
A14: Description: | C14: Short Descriptions can be added to all staff or leave blank…
A16: Work Schedule
A17: Instructions: | C17: =FormTools!B1 -> 1. MARK YOUR SCHEDULE: Use dropdown menus or begin typing to select start/end times for each day's work blocks. Leave unused blocks empty. Include location designations for each work block (Office, Remote) 2. CORE HOURS REQUIREMENT: You must routinely schedule at least 7 working hours between 7:00 AM - 5:00 PM, Monday through Thursday, unless using PTO or Travel. 3. DAILY LIMIT: Maximum 10 hours per day. Note: Non-Exempt employees are limited to 40 hours per week and all employees are limited to 75 hours per pay period, unless overtime has been approved by your supervisor. Green = Compliant, Red = Non-Compliant. Form auto-calculates totals and compliance.
C20: WEEK 1 (Pay Week)
C21: Saturday | F21: Sunday | I21: Monday | L21: Tuesday | O21: Wednesday | R21: Thursday | U21: Friday
C22: Start | D22: End | E22: Location | F22: Start | G22: End | H22: Location | I22: Start | J22: End | K22: Location | L22: Start | M22: End | N22: Location | O22: Start | P22: End | Q22: Location | R22: Start | S22: End | T22: Location | U22: Start | V22: End | W22: Location
A23: Work Block 1 | I23: 0.29166667 | J23: 0.64583333 | K23: Remote | L23: 0.29166667 | M23: 0.64583333 | N23: Remote | O23: 0.29166667 | P23: 0.64583333 | Q23: Remote | R23: 0.29166667 | S23: 0.64583333 | T23: Remote | U23: 0.29166667 | V23: 0.4375 | W23: Remote
A24: Work Block 2
A25: Work Block 3
A26: Work Block 4
A27: Work Block 5
A29: Total HRS/Day | C29: {=SUM((D23:D27-C23:C27)*24)} -> 0 | F29: {=SUM((G23:G27-F23:F27)*24)} -> 0 | I29: {=SUM((J23:J27-I23:I27)*24)} -> 8.5 | L29: {=SUM((M23:M27-L23:L27)*24)} -> 8.5 | O29: {=SUM((P23:P27-O23:O27)*24)} -> 8.5 | R29: {=SUM((S23:S27-R23:R27)*24)} -> 8.5 | U29: {=SUM((V23:V27-U23:U27)*24)} -> 3.5
A30: Total HRS/Day <=10? | C30: =C29<=10 -> TRUE | F30: =F29<=10 -> TRUE | I30: =I29<=10 -> TRUE | L30: =L29<=10 -> TRUE | O30: =O29<=10 -> TRUE | R30: =R29<=10 -> TRUE | U30: =U29<=10 -> TRUE
A31: Core Hours = 7 of 10? | C31: N/A | F31: N/A | I31: =IF(J23<>"",MAX(0,(MIN(TIME(17,0,0),J23)-MAX(TIME(7,0,0),I23))*24),0) + IF(J24<>"",MAX(0,(MIN(TIME(17,0,0),J24)-MAX(TIME(7,0,0),I24))*24),0) + IF(J25<>"",MAX(0,(MIN(TIME(17,0,0),J25)-MAX(TIME(7,0,0),I25))*24),0) + IF(J26<>"",MAX(0,(MIN(TIME(17,0,0),J26)-MAX(TIME(7,0,0),I26))*24),0) + IF(J27<>"",MAX(0,(MIN(TIME(17,0,0),J27)-MAX(TIME(7,0,0),I27))*24),0) >= 7 -> TRUE | L31: =IF(M23<>"",MAX(0,(MIN(TIME(17,0,0),M23)-MAX(TIME(7,0,0),L23))*24),0) + IF(M24<>"",MAX(0,(MIN(TIME(17,0,0),M24)-MAX(TIME(7,0,0),L24))*24),0) + IF(M25<>"",MAX(0,(MIN(TIME(17,0,0),M25)-MAX(TIME(7,0,0),L25))*24),0) + IF(M26<>"",MAX(0,(MIN(TIME(17,0,0),M26)-MAX(TIME(7,0,0),L26))*24),0) + IF(M27<>"",MAX(0,(MIN(TIME(17,0,0),M27)-MAX(TIME(7,0,0),L27))*24),0) >= 7 -> TRUE | O31: =IF(P23<>"",MAX(0,(MIN(TIME(17,0,0),P23)-MAX(TIME(7,0,0),O23))*24),0) + IF(P24<>"",MAX(0,(MIN(TIME(17,0,0),P24)-MAX(TIME(7,0,0),O24))*24),0) + IF(P25<>"",MAX(0,(MIN(TIME(17,0,0),P25)-MAX(TIME(7,0,0),O25))*24),0) + IF(P26<>"",MAX(0,(MIN(TIME(17,0,0),P26)-MAX(TIME(7,0,0),O26))*24),0) + IF(P27<>"",MAX(0,(MIN(TIME(17,0,0),P27)-MAX(TIME(7,0,0),O27))*24),0) >= 7 -> TRUE | R31: =IF(S23<>"",MAX(0,(MIN(TIME(17,0,0),S23)-MAX(TIME(7,0,0),R23))*24),0) + IF(S24<>"",MAX(0,(MIN(TIME(17,0,0),S24)-MAX(TIME(7,0,0),R24))*24),0) + IF(S25<>"",MAX(0,(MIN(TIME(17,0,0),S25)-MAX(TIME(7,0,0),R25))*24),0) + IF(S26<>"",MAX(0,(MIN(TIME(17,0,0),S26)-MAX(TIME(7,0,0),R26))*24),0) + IF(S27<>"",MAX(0,(MIN(TIME(17,0,0),S27)-MAX(TIME(7,0,0),R27))*24),0) >= 7 -> TRUE | U31: N/A
A33: Total Hours (Week 1) | C33: =SUM(C29:W29) -> 37.5
C35: WEEK 2
C36: Saturday | F36: Sunday | I36: Monday | L36: Tuesday | O36: Wednesday | R36: Thursday | U36: Friday
C37: Start | D37: End | E37: Location | F37: Start | G37: End | H37: Location | I37: Start | J37: End | K37: Location | L37: Start | M37: End | N37: Location | O37: Start | P37: End | Q37: Location | R37: Start | S37: End | T37: Location | U37: Start | V37: End | W37: Location
A38: Work Block 1 | I38: 0.29166667 | J38: 0.64583333 | K38: Remote | L38: 0.29166667 | M38: 0.64583333 | N38: Remote | O38: 0.29166667 | P38: 0.64583333 | Q38: Remote | R38: 0.29166667 | S38: 0.64583333 | T38: Remote | U38: 0.29166667 | V38: 0.4375 | W38: Remote
A39: Work Block 2
A40: Work Block 3
A41: Work Block 4
A42: Work Block 5
A44: Total HRS/Day | C44: {=SUM((D38:D42-C38:C42)*24)} -> 0 | F44: {=SUM((G38:G42-F38:F42)*24)} -> 0 | I44: {=SUM((J38:J42-I38:I42)*24)} -> 8.5 | L44: {=SUM((M38:M42-L38:L42)*24)} -> 8.5 | O44: {=SUM((P38:P42-O38:O42)*24)} -> 8.5 | R44: {=SUM((S38:S42-R38:R42)*24)} -> 8.5 | U44: {=SUM((V38:V42-U38:U42)*24)} -> 3.5
A45: Total HRS/Day <=10? | C45: =C44<=10 -> TRUE | F45: =F44<=10 -> TRUE | I45: =I44<=10 -> TRUE | L45: =L44<=10 -> TRUE | O45: =O44<=10 -> TRUE | R45: =R44<=10 -> TRUE | U45: =U44<=10 -> TRUE
A46: Core Hours = 7 of 10? | C46: N/A | F46: N/A | I46: =IF(J38<>"",MAX(0,(MIN(TIME(17,0,0),J38)-MAX(TIME(7,0,0),I38))*24),0) + IF(J39<>"",MAX(0,(MIN(TIME(17,0,0),J39)-MAX(TIME(7,0,0),I39))*24),0) + IF(J40<>"",MAX(0,(MIN(TIME(17,0,0),J40)-MAX(TIME(7,0,0),I40))*24),0) + IF(J41<>"",MAX(0,(MIN(TIME(17,0,0),J41)-MAX(TIME(7,0,0),I41))*24),0) + IF(J42<>"",MAX(0,(MIN(TIME(17,0,0),J42)-MAX(TIME(7,0,0),I42))*24),0) >= 7 -> TRUE | L46: =IF(M38<>"",MAX(0,(MIN(TIME(17,0,0),M38)-MAX(TIME(7,0,0),L38))*24),0) + IF(M39<>"",MAX(0,(MIN(TIME(17,0,0),M39)-MAX(TIME(7,0,0),L39))*24),0) + IF(M40<>"",MAX(0,(MIN(TIME(17,0,0),M40)-MAX(TIME(7,0,0),L40))*24),0) + IF(M41<>"",MAX(0,(MIN(TIME(17,0,0),M41)-MAX(TIME(7,0,0),L41))*24),0) + IF(M42<>"",MAX(0,(MIN(TIME(17,0,0),M42)-MAX(TIME(7,0,0),L42))*24),0) >= 7 -> TRUE | O46: =IF(P38<>"",MAX(0,(MIN(TIME(17,0,0),P38)-MAX(TIME(7,0,0),O38))*24),0) + IF(P39<>"",MAX(0,(MIN(TIME(17,0,0),P39)-MAX(TIME(7,0,0),O39))*24),0) + IF(P40<>"",MAX(0,(MIN(TIME(17,0,0),P40)-MAX(TIME(7,0,0),O40))*24),0) + IF(P41<>"",MAX(0,(MIN(TIME(17,0,0),P41)-MAX(TIME(7,0,0),O41))*24),0) + IF(P42<>"",MAX(0,(MIN(TIME(17,0,0),P42)-MAX(TIME(7,0,0),O42))*24),0) >= 7 -> TRUE | R46: =IF(S38<>"",MAX(0,(MIN(TIME(17,0,0),S38)-MAX(TIME(7,0,0),R38))*24),0) + IF(S39<>"",MAX(0,(MIN(TIME(17,0,0),S39)-MAX(TIME(7,0,0),R39))*24),0) + IF(S40<>"",MAX(0,(MIN(TIME(17,0,0),S40)-MAX(TIME(7,0,0),R40))*24),0) + IF(S41<>"",MAX(0,(MIN(TIME(17,0,0),S41)-MAX(TIME(7,0,0),R41))*24),0) + IF(S42<>"",MAX(0,(MIN(TIME(17,0,0),S42)-MAX(TIME(7,0,0),R42))*24),0) >= 7 -> TRUE | U46: N/A
A48: Total Hours (Week 2) | C48: =SUM(C44:W44) -> 37.5
...

Sheet Bohnert, A
A1: First Name: | C1: Ashley-Anne
A2: Last Name: | C2: Bohnert
A3: Title: | C3: Department Head, Marketing and Communications
A4: Birthdate: | C4: August 25
A5: Id: | C5: Bohnert-Ashley
A6: Direct: | C6: 724-814-3188
A7: Ext: | C7: 224
A8: Mobile: | C8: 574-485-2485
A9: Email: | C9: abohnert@tms.org
A10: Photo: | C10: BohnertAshley.jpg
A11: Dept ID: | C11: marketing
A12: Role: | C12: dept_head
A13: Reporting: | C13: Dunlap-Trudi
A14: Description: | C14: Short Descriptions can be added to all staff or leave blank…
A16: Work Schedule
A17: Instructions: | C17: =FormTools!B1 -> 1. MARK YOUR SCHEDULE: Use dropdown menus or begin typing to select start/end times for each day's work blocks. Leave unused blocks empty. Include location designations for each work block (Office, Remote) 2. CORE HOURS REQUIREMENT: You must routinely schedule at least 7 working hours between 7:00 AM - 5:00 PM, Monday through Thursday, unless using PTO or Travel. 3. DAILY LIMIT: Maximum 10 hours per day. Note: Non-Exempt employees are limited to 40 hours per week and all employees are limited to 75 hours per pay period, unless overtime has been approved by your supervisor. Green = Compliant, Red = Non-Compliant. Form auto-calculates totals and compliance.
C20: WEEK 1 (Pay Week)
C21: Saturday | F21: Sunday | I21: Monday | L21: Tuesday | O21: Wednesday | R21: Thursday | U21: Friday
C22: Start | D22: End | E22: Location | F22: Start | G22: End | H22: Location | I22: Start | J22: End | K22: Location | L22: Start | M22: End | N22: Location | O22: Start | P22: End | Q22: Location | R22: Start | S22: End | T22: Location | U22: Start | V22: End | W22: Location
A23: Work Block 1 | I23: 0.29166667 | J23: 0.3125 | K23: Remote | L23: 0.29166667 | M23: 0.3125 | N23: Remote | O23: 0.29166667 | P23: 0.3125 | Q23: Remote | R23: 0.29166667 | S23: 0.3125 | T23: Remote | U23: 0.33333333 | V23: 0.625 | W23: Remote
A24: Work Block 2 | I24: 0.33333333 | J24: 0.64583333 | K24: Remote | L24: 0.33333333 | M24: 0.64583333 | N24: Remote | O24: 0.33333333 | P24: 0.64583333 | Q24: Remote | R24: 0.33333333 | S24: 0.64583333 | T24: Remote
A25: Work Block 3 | I25: 0.875 | J25: 0.91666667 | K25: Remote | N25: Remote | R25: 0.875 | S25: 0.91666667 | T25: Remote
A26: Work Block 4
A27: Work Block 5
A29: Total HRS/Day | C29: {=SUM((D23:D27-C23:C27)*24)} -> 0 | F29: {=SUM((G23:G27-F23:F27)*24)} -> 0 | I29: {=SUM((J23:J27-I23:I27)*24)} -> 9 | L29: {=SUM((M23:M27-L23:L27)*24)} -> 8 | O29: {=SUM((P23:P27-O23:O27)*24)} -> 8 | R29: {=SUM((S23:S27-R23:R27)*24)} -> 9 | U29: {=SUM((V23:V27-U23:U27)*24)} -> 7
A30: Total HRS/Day <=10? | C30: =C29<=10 -> TRUE | F30: =F29<=10 -> TRUE | I30: =I29<=10 -> TRUE | L30: =L29<=10 -> TRUE | O30: =O29<=10 -> TRUE | R30: =R29<=10 -> TRUE | U30: =U29<=10 -> TRUE
A31: Core Hours = 7 of 10? | C31: N/A | F31: N/A | I31: =IF(J23<>"",MAX(0,(MIN(TIME(17,0,0),J23)-MAX(TIME(7,0,0),I23))*24),0) + IF(J24<>"",MAX(0,(MIN(TIME(17,0,0),J24)-MAX(TIME(7,0,0),I24))*24),0) + IF(J25<>"",MAX(0,(MIN(TIME(17,0,0),J25)-MAX(TIME(7,0,0),I25))*24),0) + IF(J26<>"",MAX(0,(MIN(TIME(17,0,0),J26)-MAX(TIME(7,0,0),I26))*24),0) + IF(J27<>"",MAX(0,(MIN(TIME(17,0,0),J27)-MAX(TIME(7,0,0),I27))*24),0) >= 7 -> TRUE | L31: =IF(M23<>"",MAX(0,(MIN(TIME(17,0,0),M23)-MAX(TIME(7,0,0),L23))*24),0) + IF(M24<>"",MAX(0,(MIN(TIME(17,0,0),M24)-MAX(TIME(7,0,0),L24))*24),0) + IF(M25<>"",MAX(0,(MIN(TIME(17,0,0),M25)-MAX(TIME(7,0,0),L25))*24),0) + IF(M26<>"",MAX(0,(MIN(TIME(17,0,0),M26)-MAX(TIME(7,0,0),L26))*24),0) + IF(M27<>"",MAX(0,(MIN(TIME(17,0,0),M27)-MAX(TIME(7,0,0),L27))*24),0) >= 7 -> TRUE | O31: =IF(P23<>"",MAX(0,(MIN(TIME(17,0,0),P23)-MAX(TIME(7,0,0),O23))*24),0) + IF(P24<>"",MAX(0,(MIN(TIME(17,0,0),P24)-MAX(TIME(7,0,0),O24))*24),0) + IF(P25<>"",MAX(0,(MIN(TIME(17,0,0),P25)-MAX(TIME(7,0,0),O25))*24),0) + IF(P26<>"",MAX(0,(MIN(TIME(17,0,0),P26)-MAX(TIME(7,0,0),O26))*24),0) + IF(P27<>"",MAX(0,(MIN(TIME(17,0,0),P27)-MAX(TIME(7,0,0),O27))*24),0) >= 7 -> TRUE | R31: =IF(S23<>"",MAX(0,(MIN(TIME(17,0,0),S23)-MAX(TIME(7,0,0),R23))*24),0) + IF(S24<>"",MAX(0,(MIN(TIME(17,0,0),S24)-MAX(TIME(7,0,0),R24))*24),0) + IF(S25<>"",MAX(0,(MIN(TIME(17,0,0),S25)-MAX(TIME(7,0,0),R25))*24),0) + IF(S26<>"",MAX(0,(MIN(TIME(17,0,0),S26)-MAX(TIME(7,0,0),R26))*24),0) + IF(S27<>"",MAX(0,(MIN(TIME(17,0,0),S27)-MAX(TIME(7,0,0),R27))*24),0) >= 7 -> TRUE | U31: N/A
A33: Total Hours (Week 1) | C33: =SUM(C29:W29) -> 41
C35: WEEK 2
C36: Saturday | F36: Sunday | I36: Monday | L36: Tuesday | O36: Wednesday | R36: Thursday | U36: Friday
C37: Start | D37: End | E37: Location | F37: Start | G37: End | H37: Location | I37: Start | J37: End | K37: Location | L37: Start | M37: End | N37: Location | O37: Start | P37: End | Q37: Location | R37: Start | S37: End | T37: Location | U37: Start | V37: End | W37: Location
A38: Work Block 1 | I38: 0.29166667 | J38: 0.3125 | K38: Remote | L38: 0.29166667 | M38: 0.3125 | N38: Remote | O38: 0.29166667 | P38: 0.3125 | Q38: Remote | R38: 0.29166667 | S38: 0.3125 | T38: Remote
A39: Work Block 2 | I39: 0.33333333 | J39: 0.64583333 | K39: Remote | L39: 0.33333333 | M39: 0.64583333 | N39: Remote | O39: 0.33333333 | P39: 0.64583333 | Q39: Remote | R39: 0.33333333 | S39: 0.64583333 | T39: Remote
A40: Work Block 3 | I40: 0.91666667 | J40: 0.95833333 | K40: Remote | N40: Remote | R40: 0.875 | S40: 0.91666667 | T40: Remote
A41: Work Block 4
A42: Work Block 5
A44: Total HRS/Day | C44: {=SUM((D38:D42-C38:C42)*24)} -> 0 | F44: {=SUM((G38:G42-F38:F42)*24)} -> 0 | I44: {=SUM((J38:J42-I38:I42)*24)} -> 9 | L44: {=SUM((M38:M42-L38:L42)*24)} -> 8 | O44: {=SUM((P38:P42-O38:O42)*24)} -> 8 | R44: {=SUM((S38:S42-R38:R42)*24)} -> 9 | U44: {=SUM((V38:V42-U38:U42)*24)} -> 0
A45: Total HRS/Day <=10? | C45: =C44<=10 -> TRUE | F45: =F44<=10 -> TRUE | I45: =I44<=10 -> TRUE | L45: =L44<=10 -> TRUE | O45: =O44<=10 -> TRUE | R45: =R44<=10 -> TRUE | U45: =U44<=10 -> TRUE
A46: Core Hours = 7 of 10? | C46: N/A | F46: N/A | I46: =IF(J38<>"",MAX(0,(MIN(TIME(17,0,0),J38)-MAX(TIME(7,0,0),I38))*24),0) + IF(J39<>"",MAX(0,(MIN(TIME(17,0,0),J39)-MAX(TIME(7,0,0),I39))*24),0) + IF(J40<>"",MAX(0,(MIN(TIME(17,0,0),J40)-MAX(TIME(7,0,0),I40))*24),0) + IF(J41<>"",MAX(0,(MIN(TIME(17,0,0),J41)-MAX(TIME(7,0,0),I41))*24),0) + IF(J42<>"",MAX(0,(MIN(TIME(17,0,0),J42)-MAX(TIME(7,0,0),I42))*24),0) >= 7 -> TRUE | L46: =IF(M38<>"",MAX(0,(MIN(TIME(17,0,0),M38)-MAX(TIME(7,0,0),L38))*24),0) + IF(M39<>"",MAX(0,(MIN(TIME(17,0,0),M39)-MAX(TIME(7,0,0),L39))*24),0) + IF(M40<>"",MAX(0,(MIN(TIME(17,0,0),M40)-MAX(TIME(7,0,0),L40))*24),0) + IF(M41<>"",MAX(0,(MIN(TIME(17,0,0),M41)-MAX(TIME(7,0,0),L41))*24),0) + IF(M42<>"",MAX(0,(MIN(TIME(17,0,0),M42)-MAX(TIME(7,0,0),L42))*24),0) >= 7 -> TRUE | O46: =IF(P38<>"",MAX(0,(MIN(TIME(17,0,0),P38)-MAX(TIME(7,0,0),O38))*24),0) + IF(P39<>"",MAX(0,(MIN(TIME(17,0,0),P39)-MAX(TIME(7,0,0),O39))*24),0) + IF(P40<>"",MAX(0,(MIN(TIME(17,0,0),P40)-MAX(TIME(7,0,0),O40))*24),0) + IF(P41<>"",MAX(0,(MIN(TIME(17,0,0),P41)-MAX(TIME(7,0,0),O41))*24),0) + IF(P42<>"",MAX(0,(MIN(TIME(17,0,0),P42)-MAX(TIME(7,0,0),O42))*24),0) >= 7 -> TRUE | R46: =IF(S38<>"",MAX(0,(MIN(TIME(17,0,0),S38)-MAX(TIME(7,0,0),R38))*24),0) + IF(S39<>"",MAX(0,(MIN(TIME(17,0,0),S39)-MAX(TIME(7,0,0),R39))*24),0) + IF(S40<>"",MAX(0,(MIN(TIME(17,0,0),S40)-MAX(TIME(7,0,0),R40))*24),0) + IF(S41<>"",MAX(0,(MIN(TIME(17,0,0),S41)-MAX(TIME(7,0,0),R41))*24),0) + IF(S42<>"",MAX(0,(MIN(TIME(17,0,0),S42)-MAX(TIME(7,0,0),R42))*24),0) >= 7 -> TRUE | U46: N/A
A48: Total Hours (Week 2) | C48: =SUM(C44:W44) -> 34
...

Sheet Carolla, A
A1: First Name: | C1: Adrianne
A2: Last Name: | C2: Carolla
A3: Title: | C3: Deputy Executive Director
A4: Birthdate: | C4: June 3
A5: Id: | C5: Carolla-Adrianne
A6: Direct: | C6: 724-814-3180
A7: Ext: | C7: 219
A8: Mobile: | C8: 412-720-7771
A9: Email: | C9: acarolla@tms.org
A10: Photo: | C10: CarollaAdrianne.jpg
A11: Dept ID: | C11: executive
A12: Role: | C12: deputy
A13: Reporting: | C13: Dunlap-Trudi
A14: Description: | C14: Short Descriptions can be added to all staff or leave blank…
A16: Work Schedule
A17: Instructions: | C17: =FormTools!B1 -> 1. MARK YOUR SCHEDULE: Use dropdown menus or begin typing to select start/end times for each day's work blocks. Leave unused blocks empty. Include location designations for each work block (Office, Remote) 2. CORE HOURS REQUIREMENT: You must routinely schedule at least 7 working hours between 7:00 AM - 5:00 PM, Monday through Thursday, unless using PTO or Travel. 3. DAILY LIMIT: Maximum 10 hours per day. Note: Non-Exempt employees are limited to 40 hours per week and all employees are limited to 75 hours per pay period, unless overtime has been approved by your supervisor. Green = Compliant, Red = Non-Compliant. Form auto-calculates totals and compliance.
C20: WEEK 1 (Pay Week)
C21: Saturday | F21: Sunday | I21: Monday | L21: Tuesday | O21: Wednesday | R21: Thursday | U21: Friday
C22: Start | D22: End | E22: Location | F22: Start | G22: End | H22: Location | I22: Start | J22: End | K22: Location | L22: Start | M22: End | N22: Location | O22: Start | P22: End | Q22: Location | R22: Start | S22: End | T22: Location | U22: Start | V22: End | W22: Location
A23: Work Block 1 | I23: 0.3125 | J23: 0.375 | K23: Remote | L23: 0.3125 | M23: 0.4375 | N23: Remote | O23: 0.35416667 | P23: 0.72916667 | Q23: Office | R23: 0.35416667 | S23: 0.72916667 | T23: Office | U23: 0.3125 | V23: 0.375 | W23: Remote
A24: Work Block 2 | I24: 0.4375 | J24: 0.72916667 | K24: Remote | L24: 0.5 | M24: 0.72916667 | N24: Remote | U24: 0.5 | V24: 0.64583333 | W24: Remote
A25: Work Block 3
A26: Work Block 4
A27: Work Block 5
A29: Total HRS/Day | C29: {=SUM((D23:D27-C23:C27)*24)} -> 0 | F29: {=SUM((G23:G27-F23:F27)*24)} -> 0 | I29: {=SUM((J23:J27-I23:I27)*24)} -> 8.5 | L29: {=SUM((M23:M27-L23:L27)*24)} -> 8.5 | O29: {=SUM((P23:P27-O23:O27)*24)} -> 9 | R29: {=SUM((S23:S27-R23:R27)*24)} -> 9 | U29: {=SUM((V23:V27-U23:U27)*24)} -> 5
A30: Total HRS/Day <=10? | C30: =C29<=10 -> TRUE | F30: =F29<=10 -> TRUE | I30: =I29<=10 -> TRUE | L30: =L29<=10 -> TRUE | O30: =O29<=10 -> TRUE | R30: =R29<=10 -> TRUE | U30: =U29<=10 -> TRUE
A31: Core Hours = 7 of 10? | C31: N/A | F31: N/A | I31: =IF(J23<>"",MAX(0,(MIN(TIME(17,0,0),J23)-MAX(TIME(7,0,0),I23))*24),0) + IF(J24<>"",MAX(0,(MIN(TIME(17,0,0),J24)-MAX(TIME(7,0,0),I24))*24),0) + IF(J25<>"",MAX(0,(MIN(TIME(17,0,0),J25)-MAX(TIME(7,0,0),I25))*24),0) + IF(J26<>"",MAX(0,(MIN(TIME(17,0,0),J26)-MAX(TIME(7,0,0),I26))*24),0) + IF(J27<>"",MAX(0,(MIN(TIME(17,0,0),J27)-MAX(TIME(7,0,0),I27))*24),0) >= 7 -> TRUE | L31: =IF(M23<>"",MAX(0,(MIN(TIME(17,0,0),M23)-MAX(TIME(7,0,0),L23))*24),0) + IF(M24<>"",MAX(0,(MIN(TIME(17,0,0),M24)-MAX(TIME(7,0,0),L24))*24),0) + IF(M25<>"",MAX(0,(MIN(TIME(17,0,0),M25)-MAX(TIME(7,0,0),L25))*24),0) + IF(M26<>"",MAX(0,(MIN(TIME(17,0,0),M26)-MAX(TIME(7,0,0),L26))*24),0) + IF(M27<>"",MAX(0,(MIN(TIME(17,0,0),M27)-MAX(TIME(7,0,0),L27))*24),0) >= 7 -> TRUE | O31: =IF(P23<>"",MAX(0,(MIN(TIME(17,0,0),P23)-MAX(TIME(7,0,0),O23))*24),0) + IF(P24<>"",MAX(0,(MIN(TIME(17,0,0),P24)-MAX(TIME(7,0,0),O24))*24),0) + IF(P25<>"",MAX(0,(MIN(TIME(17,0,0),P25)-MAX(TIME(7,0,0),O25))*24),0) + IF(P26<>"",MAX(0,(MIN(TIME(17,0,0),P26)-MAX(TIME(7,0,0),O26))*24),0) + IF(P27<>"",MAX(0,(MIN(TIME(17,0,0),P27)-MAX(TIME(7,0,0),O27))*24),0) >= 7 -> TRUE | R31: =IF(S23<>"",MAX(0,(MIN(TIME(17,0,0),S23)-MAX(TIME(7,0,0),R23))*24),0) + IF(S24<>"",MAX(0,(MIN(TIME(17,0,0),S24)-MAX(TIME(7,0,0),R24))*24),0) + IF(S25<>"",MAX(0,(MIN(TIME(17,0,0),S25)-MAX(TIME(7,0,0),R25))*24),0) + IF(S26<>"",MAX(0,(MIN(TIME(17,0,0),S26)-MAX(TIME(7,0,0),R26))*24),0) + IF(S27<>"",MAX(0,(MIN(TIME(17,0,0),S27)-MAX(TIME(7,0,0),R27))*24),0) >= 7 -> TRUE | U31: N/A
A33: Total Hours (Week 1) | C33: =SUM(C29:W29) -> 40
C35: WEEK 2
C36: Saturday | F36: Sunday | I36: Monday | L36: Tuesday | O36: Wednesday | R36: Thursday | U36: Friday
C37: Start | D37: End | E37: Location | F37: Start | G37: End | H37: Location | I37: Start | J37: End | K37: Location | L37: Start | M37: End | N37: Location | O37: Start | P37: End | Q37: Location | R37: Start | S37: End | T37: Location | U37: Start | V37: End | W37: Location
A38: Work Block 1 | I38: 0.3125 | J38: 0.375 | K38: Remote | L38: 0.3125 | M38: 0.4375 | N38: Remote | O38: 0.35416667 | P38: 0.72916667 | Q38: Office | R38: 0.35416667 | S38: 0.72916667 | T38: Office
A39: Work Block 2 | I39: 0.4375 | J39: 0.72916667 | K39: Remote | L39: 0.5 | M39: 0.72916667 | N39: Remote
A40: Work Block 3
A41: Work Block 4
A42: Work Block 5
A44: Total HRS/Day | C44: {=SUM((D38:D42-C38:C42)*24)} -> 0 | F44: {=SUM((G38:G42-F38:F42)*24)} -> 0 | I44: {=SUM((J38:J42-I38:I42)*24)} -> 8.5 | L44: {=SUM((M38:M42-L38:L42)*24)} -> 8.5 | O44: {=SUM((P38:P42-O38:O42)*24)} -> 9 | R44: {=SUM((S38:S42-R38:R42)*24)} -> 9 | U44: {=SUM((V38:V42-U38:U42)*24)} -> 0
A45: Total HRS/Day <=10? | C45: =C44<=10 -> TRUE | F45: =F44<=10 -> TRUE | I45: =I44<=10 -> TRUE | L45: =L44<=10 -> TRUE | O45: =O44<=10 -> TRUE | R45: =R44<=10 -> TRUE | U45: =U44<=10 -> TRUE
A46: Core Hours = 7 of 10? | C46: N/A | F46: N/A | I46: =IF(J38<>"",MAX(0,(MIN(TIME(17,0,0),J38)-MAX(TIME(7,0,0),I38))*24),0) + IF(J39<>"",MAX(0,(MIN(TIME(17,0,0),J39)-MAX(TIME(7,0,0),I39))*24),0) + IF(J40<>"",MAX(0,(MIN(TIME(17,0,0),J40)-MAX(TIME(7,0,0),I40))*24),0) + IF(J41<>"",MAX(0,(MIN(TIME(17,0,0),J41)-MAX(TIME(7,0,0),I41))*24),0) + IF(J42<>"",MAX(0,(MIN(TIME(17,0,0),J42)-MAX(TIME(7,0,0),I42))*24),0) >= 7 -> TRUE | L46: =IF(M38<>"",MAX(0,(MIN(TIME(17,0,0),M38)-MAX(TIME(7,0,0),L38))*24),0) + IF(M39<>"",MAX(0,(MIN(TIME(17,0,0),M39)-MAX(TIME(7,0,0),L39))*24),0) + IF(M40<>"",MAX(0,(MIN(TIME(17,0,0),M40)-MAX(TIME(7,0,0),L40))*24),0) + IF(M41<>"",MAX(0,(MIN(TIME(17,0,0),M41)-MAX(TIME(7,0,0),L41))*24),0) + IF(M42<>"",MAX(0,(MIN(TIME(17,0,0),M42)-MAX(TIME(7,0,0),L42))*24),0) >= 7 -> TRUE | O46: =IF(P38<>"",MAX(0,(MIN(TIME(17,0,0),P38)-MAX(TIME(7,0,0),O38))*24),0) + IF(P39<>"",MAX(0,(MIN(TIME(17,0,0),P39)-MAX(TIME(7,0,0),O39))*24),0) + IF(P40<>"",MAX(0,(MIN(TIME(17,0,0),P40)-MAX(TIME(7,0,0),O40))*24),0) + IF(P41<>"",MAX(0,(MIN(TIME(17,0,0),P41)-MAX(TIME(7,0,0),O41))*24),0) + IF(P42<>"",MAX(0,(MIN(TIME(17,0,0),P42)-MAX(TIME(7,0,0),O42))*24),0) >= 7 -> TRUE | R46: =IF(S38<>"",MAX(0,(MIN(TIME(17,0,0),S38)-MAX(TIME(7,0,0),R38))*24),0) + IF(S39<>"",MAX(0,(MIN(TIME(17,0,0),S39)-MAX(TIME(7,0,0),R39))*24),0) + IF(S40<>"",MAX(0,(MIN(TIME(17,0,0),S40)-MAX(TIME(7,0,0),R40))*24),0) + IF(S41<>"",MAX(0,(MIN(TIME(17,0,0),S41)-MAX(TIME(7,0,0),R41))*24),0) + IF(S42<>"",MAX(0,(MIN(TIME(17,0,0),S42)-MAX(TIME(7,0,0),R42))*24),0) >= 7 -> TRUE | U46: N/A
A48: Total Hours (Week 2) | C48: =SUM(C44:W44) -> 35
...

Sheet Davis, A
A1: First Name: | C1: Abby
A2: Last Name: | C2: Davis
A3: Title: | C3: Sales and Exhibition Specialist
A4: Birthdate: | C4: December 3
A5: Id: | C5: Davis-Abby
A6: Direct: | C6: 724-814-3140
A7: Ext: | C7: 231
A8: Mobile: | C8: 513-320-7744
A9: Email: | C9: adavis@tms.org
A10: Photo: | C10: DavisAbby.jpg
A11: Dept ID: | C11: events
A12: Role: | C12: staff
A13: Reporting: | C13: Parsson-Kellye
A14: Description: | C14: Short Descriptions can be added to all staff or leave blank…
A16: Work Schedule
A17: Instructions: | C17: =FormTools!B1 -> 1. MARK YOUR SCHEDULE: Use dropdown menus or begin typing to select start/end times for each day's work blocks. Leave unused blocks empty. Include location designations for each work block (Office, Remote) 2. CORE HOURS REQUIREMENT: You must routinely schedule at least 7 working hours between 7:00 AM - 5:00 PM, Monday through Thursday, unless using PTO or Travel. 3. DAILY LIMIT: Maximum 10 hours per day. Note: Non-Exempt employees are limited to 40 hours per week and all employees are limited to 75 hours per pay period, unless overtime has been approved by your supervisor. Green = Compliant, Red = Non-Compliant. Form auto-calculates totals and compliance.
C20: WEEK 1 (Pay Week)
C21: Saturday | F21: Sunday | I21: Monday | L21: Tuesday | O21: Wednesday | R21: Thursday | U21: Friday
C22: Start | D22: End | E22: Location | F22: Start | G22: End | H22: Location | I22: Start | J22: End | K22: Location | L22: Start | M22: End | N22: Location | O22: Start | P22: End | Q22: Location | R22: Start | S22: End | T22: Location | U22: Start | V22: End | W22: Location
A23: Work Block 1 | I23: 0.33333333 | J23: 0.5 | K23: Office | L23: 0.33333333 | M23: 0.5 | N23: Office | O23: 0.33333333 | P23: 0.5 | Q23: Office | R23: 0.33333333 | S23: 0.5 | T23: Office | U23: 0.33333333 | V23: 0.5 | W23: Office
A24: Work Block 2 | I24: 0.52083333 | J24: 0.70833333 | K24: Office | L24: 0.52083333 | M24: 0.70833333 | N24: Office | O24: 0.52083333 | P24: 0.70833333 | Q24: Office | R24: 0.52083333 | S24: 0.70833333 | T24: Office | U24: 0.52083333 | V24: 0.64583333 | W24: Office
A25: Work Block 3
A26: Work Block 4
A27: Work Block 5
A29: Total HRS/Day | C29: {=SUM((D23:D27-C23:C27)*24)} -> 0 | F29: {=SUM((G23:G27-F23:F27)*24)} -> 0 | I29: {=SUM((J23:J27-I23:I27)*24)} -> 8.5 | L29: {=SUM((M23:M27-L23:L27)*24)} -> 8.5 | O29: {=SUM((P23:P27-O23:O27)*24)} -> 8.5 | R29: {=SUM((S23:S27-R23:R27)*24)} -> 8.5 | U29: {=SUM((V23:V27-U23:U27)*24)} -> 7
A30: Total HRS/Day <=10? | C30: =C29<=10 -> TRUE | F30: =F29<=10 -> TRUE | I30: =I29<=10 -> TRUE | L30: =L29<=10 -> TRUE | O30: =O29<=10 -> TRUE | R30: =R29<=10 -> TRUE | U30: =U29<=10 -> TRUE
A31: Core Hours = 7 of 10? | C31: N/A | F31: N/A | I31: =IF(J23<>"",MAX(0,(MIN(TIME(17,0,0),J23)-MAX(TIME(7,0,0),I23))*24),0) + IF(J24<>"",MAX(0,(MIN(TIME(17,0,0),J24)-MAX(TIME(7,0,0),I24))*24),0) + IF(J25<>"",MAX(0,(MIN(TIME(17,0,0),J25)-MAX(TIME(7,0,0),I25))*24),0) + IF(J26<>"",MAX(0,(MIN(TIME(17,0,0),J26)-MAX(TIME(7,0,0),I26))*24),0) + IF(J27<>"",MAX(0,(MIN(TIME(17,0,0),J27)-MAX(TIME(7,0,0),I27))*24),0) >= 7 -> TRUE | L31: =IF(M23<>"",MAX(0,(MIN(TIME(17,0,0),M23)-MAX(TIME(7,0,0),L23))*24),0) + IF(M24<>"",MAX(0,(MIN(TIME(17,0,0),M24)-MAX(TIME(7,0,0),L24))*24),0) + IF(M25<>"",MAX(0,(MIN(TIME(17,0,0),M25)-MAX(TIME(7,0,0),L25))*24),0) + IF(M26<>"",MAX(0,(MIN(TIME(17,0,0),M26)-MAX(TIME(7,0,0),L26))*24),0) + IF(M27<>"",MAX(0,(MIN(TIME(17,0,0),M27)-MAX(TIME(7,0,0),L27))*24),0) >= 7 -> TRUE | O31: =IF(P23<>"",MAX(0,(MIN(TIME(17,0,0),P23)-MAX(TIME(7,0,0),O23))*24),0) + IF(P24<>"",MAX(0,(MIN(TIME(17,0,0),P24)-MAX(TIME(7,0,0),O24))*24),0) + IF(P25<>"",MAX(0,(MIN(TIME(17,0,0),P25)-MAX(TIME(7,0,0),O25))*24),0) + IF(P26<>"",MAX(0,(MIN(TIME(17,0,0),P26)-MAX(TIME(7,0,0),O26))*24),0) + IF(P27<>"",MAX(0,(MIN(TIME(17,0,0),P27)-MAX(TIME(7,0,0),O27))*24),0) >= 7 -> TRUE | R31: =IF(S23<>"",MAX(0,(MIN(TIME(17,0,0),S23)-MAX(TIME(7,0,0),R23))*24),0) + IF(S24<>"",MAX(0,(MIN(TIME(17,0,0),S24)-MAX(TIME(7,0,0),R24))*24),0) + IF(S25<>"",MAX(0,(MIN(TIME(17,0,0),S25)-MAX(TIME(7,0,0),R25))*24),0) + IF(S26<>"",MAX(0,(MIN(TIME(17,0,0),S26)-MAX(TIME(7,0,0),R26))*24),0) + IF(S27<>"",MAX(0,(MIN(TIME(17,0,0),S27)-MAX(TIME(7,0,0),R27))*24),0) >= 7 -> TRUE | U31: N/A
A33: Total Hours (Week 1) | C33: =SUM(C29:W29) -> 41
C35: WEEK 2
C36: Saturday | F36: Sunday | I36: Monday | L36: Tuesday | O36: Wednesday | R36: Thursday | U36: Friday
C37: Start | D37: End | E37: Location | F37: Start | G37: End | H37: Location | I37: Start | J37: End | K37: Location | L37: Start | M37: End | N37: Location | O37: Start | P37: End | Q37: Location | R37: Start | S37: End | T37: Location | U37: Start | V37: End | W37: Location
A38: Work Block 1 | I38: 0.33333333 | J38: 0.5 | K38: Office | L38: 0.33333333 | M38: 0.5 | N38: Office | O38: 0.33333333 | P38: 0.5 | Q38: Office | R38: 0.33333333 | S38: 0.5 | T38: Office
A39: Work Block 2 | I39: 0.52083333 | J39: 0.70833333 | K39: Office | L39: 0.52083333 | M39: 0.70833333 | N39: Office | O39: 0.52083333 | P39: 0.70833333 | Q39: Office | R39: 0.52083333 | S39: 0.70833333 | T39: Office
A40: Work Block 3
A41: Work Block 4
A42: Work Block 5
A44: Total HRS/Day | C44: {=SUM((D38:D42-C38:C42)*24)} -> 0 | F44: {=SUM((G38:G42-F38:F42)*24)} -> 0 | I44: {=SUM((J38:J42-I38:I42)*24)} -> 8.5 | L44: {=SUM((M38:M42-L38:L42)*24)} -> 8.5 | O44: {=SUM((P38:P42-O38:O42)*24)} -> 8.5 | R44: {=SUM((S38:S42-R38:R42)*24)} -> 8.5 | U44: {=SUM((V38:V42-U38:U42)*24)} -> 0
A45: Total HRS/Day <=10? | C45: =C44<=10 -> TRUE | F45: =F44<=10 -> TRUE | I45: =I44<=10 -> TRUE | L45: =L44<=10 -> TRUE | O45: =O44<=10 -> TRUE | R45: =R44<=10 -> TRUE | U45: =U44<=10 -> TRUE
A46: Core Hours = 7 of 10? | C46: N/A | F46: N/A | I46: =IF(J38<>"",MAX(0,(MIN(TIME(17,0,0),J38)-MAX(TIME(7,0,0),I38))*24),0) + IF(J39<>"",MAX(0,(MIN(TIME(17,0,0),J39)-MAX(TIME(7,0,0),I39))*24),0) + IF(J40<>"",MAX(0,(MIN(TIME(17,0,0),J40)-MAX(TIME(7,0,0),I40))*24),0) + IF(J41<>"",MAX(0,(MIN(TIME(17,0,0),J41)-MAX(TIME(7,0,0),I41))*24),0) + IF(J42<>"",MAX(0,(MIN(TIME(17,0,0),J42)-MAX(TIME(7,0,0),I42))*24),0) >= 7 -> TRUE | L46: =IF(M38<>"",MAX(0,(MIN(TIME(17,0,0),M38)-MAX(TIME(7,0,0),L38))*24),0) + IF(M39<>"",MAX(0,(MIN(TIME(17,0,0),M39)-MAX(TIME(7,0,0),L39))*24),0) + IF(M40<>"",MAX(0,(MIN(TIME(17,0,0),M40)-MAX(TIME(7,0,0),L40))*24),0) + IF(M41<>"",MAX(0,(MIN(TIME(17,0,0),M41)-MAX(TIME(7,0,0),L41))*24),0) + IF(M42<>"",MAX(0,(MIN(TIME(17,0,0),M42)-MAX(TIME(7,0,0),L42))*24),0) >= 7 -> TRUE | O46: =IF(P38<>"",MAX(0,(MIN(TIME(17,0,0),P38)-MAX(TIME(7,0,0),O38))*24),0) + IF(P39<>"",MAX(0,(MIN(TIME(17,0,0),P39)-MAX(TIME(7,0,0),O39))*24),0) + IF(P40<>"",MAX(0,(MIN(TIME(17,0,0),P40)-MAX(TIME(7,0,0),O40))*24),0) + IF(P41<>"",MAX(0,(MIN(TIME(17,0,0),P41)-MAX(TIME(7,0,0),O41))*24),0) + IF(P42<>"",MAX(0,(MIN(TIME(17,0,0),P42)-MAX(TIME(7,0,0),O42))*24),0) >= 7 -> TRUE | R46: =IF(S38<>"",MAX(0,(MIN(TIME(17,0,0),S38)-MAX(TIME(7,0,0),R38))*24),0) + IF(S39<>"",MAX(0,(MIN(TIME(17,0,0),S39)-MAX(TIME(7,0,0),R39))*24),0) + IF(S40<>"",MAX(0,(MIN(TIME(17,0,0),S40)-MAX(TIME(7,0,0),R40))*24),0) + IF(S41<>"",MAX(0,(MIN(TIME(17,0,0),S41)-MAX(TIME(7,0,0),R41))*24),0) + IF(S42<>"",MAX(0,(MIN(TIME(17,0,0),S42)-MAX(TIME(7,0,0),R42))*24),0) >= 7 -> TRUE | U46: N/A
A48: Total Hours (Week 2) | C48: =SUM(C44:W44) -> 34
...

Sheet Demmler, R
A1: First Name: | C1: Robert
A2: Last Name: | C2: Demmler
A3: Title: | C3: AI Integration and Visual Communications Specialist
A4: Birthdate: | C4: July 29
A5: Id: | C5: Demmler-Robert
A6: Direct: | C6: 724-814-3120
A7: Ext: | C7: 217
A8: Mobile: | C8: 412-245-0326
A9: Email: | C9: bdemmler@tms.org
A10: Photo: | C10: DemmlerRobert.jpg
A11: Dept ID: | C11: marketing
A12: Role: | C12: staff
A13: Reporting: | C13: Rasel-Dave
A14: Description: | C14: Short Descriptions can be added to all staff or leave blank…
A16: Work Schedule
A17: Instructions: | C17: =FormTools!B1 -> 1. MARK YOUR SCHEDULE: Use dropdown menus or begin typing to select start/end times for each day's work blocks. Leave unused blocks empty. Include location designations for each work block (Office, Remote) 2. CORE HOURS REQUIREMENT: You must routinely schedule at least 7 working hours between 7:00 AM - 5:00 PM, Monday through Thursday, unless using PTO or Travel. 3. DAILY LIMIT: Maximum 10 hours per day. Note: Non-Exempt employees are limited to 40 hours per week and all employees are limited to 75 hours per pay period, unless overtime has been approved by your supervisor. Green = Compliant, Red = Non-Compliant. Form auto-calculates totals and compliance.
C20: WEEK 1 (Pay Week)
C21: Saturday | F21: Sunday | I21: Monday | L21: Tuesday | O21: Wednesday | R21: Thursday | U21: Friday
C22: Start | D22: End | E22: Location | F22: Start | G22: End | H22: Location | I22: Start | J22: End | K22: Location | L22: Start | M22: End | N22: Location | O22: Start | P22: End | Q22: Location | R22: Start | S22: End | T22: Location | U22: Start | V22: End | W22: Location
A23: Work Block 1 | I23: 0.27083333 | J23: 0.64583333 | K23: Remote | L23: 0.27083333 | M23: 0.64583333 | N23: Remote | O23: 0.27083333 | P23: 0.64583333 | Q23: Office | R23: 0.27083333 | S23: 0.64583333 | T23: Remote
A24: Work Block 2
A25: Work Block 3
A26: Work Block 4
A27: Work Block 5
A29: Total HRS/Day | C29: {=SUM((D23:D27-C23:C27)*24)} -> 0 | F29: {=SUM((G23:G27-F23:F27)*24)} -> 0 | I29: {=SUM((J23:J27-I23:I27)*24)} -> 9 | L29: {=SUM((M23:M27-L23:L27)*24)} -> 9 | O29: {=SUM((P23:P27-O23:O27)*24)} -> 9 | R29: {=SUM((S23:S27-R23:R27)*24)} -> 9 | U29: {=SUM((V23:V27-U23:U27)*24)} -> 0
A30: Total HRS/Day <=10? | C30: =C29<=10 -> TRUE | F30: =F29<=10 -> TRUE | I30: =I29<=10 -> TRUE | L30: =L29<=10 -> TRUE | O30: =O29<=10 -> TRUE | R30: =R29<=10 -> TRUE | U30: =U29<=10 -> TRUE
A31: Core Hours = 7 of 10? | C31: N/A | F31: N/A | I31: =IF(J23<>"",MAX(0,(MIN(TIME(17,0,0),J23)-MAX(TIME(7,0,0),I23))*24),0) + IF(J24<>"",MAX(0,(MIN(TIME(17,0,0),J24)-MAX(TIME(7,0,0),I24))*24),0) + IF(J25<>"",MAX(0,(MIN(TIME(17,0,0),J25)-MAX(TIME(7,0,0),I25))*24),0) + IF(J26<>"",MAX(0,(MIN(TIME(17,0,0),J26)-MAX(TIME(7,0,0),I26))*24),0) + IF(J27<>"",MAX(0,(MIN(TIME(17,0,0),J27)-MAX(TIME(7,0,0),I27))*24),0) >= 7 -> TRUE | L31: =IF(M23<>"",MAX(0,(MIN(TIME(17,0,0),M23)-MAX(TIME(7,0,0),L23))*24),0) + IF(M24<>"",MAX(0,(MIN(TIME(17,0,0),M24)-MAX(TIME(7,0,0),L24))*24),0) + IF(M25<>"",MAX(0,(MIN(TIME(17,0,0),M25)-MAX(TIME(7,0,0),L25))*24),0) + IF(M26<>"",MAX(0,(MIN(TIME(17,0,0),M26)-MAX(TIME(7,0,0),L26))*24),0) + IF(M27<>"",MAX(0,(MIN(TIME(17,0,0),M27)-MAX(TIME(7,0,0),L27))*24),0) >= 7 -> TRUE | O31: =IF(P23<>"",MAX(0,(MIN(TIME(17,0,0),P23)-MAX(TIME(7,0,0),O23))*24),0) + IF(P24<>"",MAX(0,(MIN(TIME(17,0,0),P24)-MAX(TIME(7,0,0),O24))*24),0) + IF(P25<>"",MAX(0,(MIN(TIME(17,0,0),P25)-MAX(TIME(7,0,0),O25))*24),0) + IF(P26<>"",MAX(0,(MIN(TIME(17,0,0),P26)-MAX(TIME(7,0,0),O26))*24),0) + IF(P27<>"",MAX(0,(MIN(TIME(17,0,0),P27)-MAX(TIME(7,0,0),O27))*24),0) >= 7 -> TRUE | R31: =IF(S23<>"",MAX(0,(MIN(TIME(17,0,0),S23)-MAX(TIME(7,0,0),R23))*24),0) + IF(S24<>"",MAX(0,(MIN(TIME(17,0,0),S24)-MAX(TIME(7,0,0),R24))*24),0) + IF(S25<>"",MAX(0,(MIN(TIME(17,0,0),S25)-MAX(TIME(7,0,0),R25))*24),0) + IF(S26<>"",MAX(0,(MIN(TIME(17,0,0),S26)-MAX(TIME(7,0,0),R26))*24),0) + IF(S27<>"",MAX(0,(MIN(TIME(17,0,0),S27)-MAX(TIME(7,0,0),R27))*24),0) >= 7 -> TRUE | U31: N/A
A33: Total Hours (Week 1) | C33: =SUM(C29:W29) -> 36
C35: WEEK 2
C36: Saturday | F36: Sunday | I36: Monday | L36: Tuesday | O36: Wednesday | R36: Thursday | U36: Friday
C37: Start | D37: End | E37: Location | F37: Start | G37: End | H37: Location | I37: Start | J37: End | K37: Location | L37: Start | M37: End | N37: Location | O37: Start | P37: End | Q37: Location | R37: Start | S37: End | T37: Location | U37: Start | V37: End | W37: Location
A38: Work Block 1 | I38: 0.27083333 | J38: 0.64583333 | K38: Remote | L38: 0.27083333 | M38: 0.64583333 | N38: Remote | O38: 0.27083333 | P38: 0.64583333 | Q38: Office | R38: 0.27083333 | S38: 0.64583333 | T38: Remote | U38: 0.27083333 | V38: 0.39583333 | W38: Remote
A39: Work Block 2
A40: Work Block 3
A41: Work Block 4
A42: Work Block 5
A44: Total HRS/Day | C44: {=SUM((D38:D42-C38:C42)*24)} -> 0 | F44: {=SUM((G38:G42-F38:F42)*24)} -> 0 | I44: {=SUM((J38:J42-I38:I42)*24)} -> 9 | L44: {=SUM((M38:M42-L38:L42)*24)} -> 9 | O44: {=SUM((P38:P42-O38:O42)*24)} -> 9 | R44: {=SUM((S38:S42-R38:R42)*24)} -> 9 | U44: {=SUM((V38:V42-U38:U42)*24)} -> 3
A45: Total HRS/Day <=10? | C45: =C44<=10 -> TRUE | F45: =F44<=10 -> TRUE | I45: =I44<=10 -> TRUE | L45: =L44<=10 -> TRUE | O45: =O44<=10 -> TRUE | R45: =R44<=10 -> TRUE | U45: =U44<=10 -> TRUE
A46: Core Hours = 7 of 10? | C46: N/A | F46: N/A | I46: =IF(J38<>"",MAX(0,(MIN(TIME(17,0,0),J38)-MAX(TIME(7,0,0),I38))*24),0) + IF(J39<>"",MAX(0,(MIN(TIME(17,0,0),J39)-MAX(TIME(7,0,0),I39))*24),0) + IF(J40<>"",MAX(0,(MIN(TIME(17,0,0),J40)-MAX(TIME(7,0,0),I40))*24),0) + IF(J41<>"",MAX(0,(MIN(TIME(17,0,0),J41)-MAX(TIME(7,0,0),I41))*24),0) + IF(J42<>"",MAX(0,(MIN(TIME(17,0,0),J42)-MAX(TIME(7,0,0),I42))*24),0) >= 7 -> TRUE | L46: =IF(M38<>"",MAX(0,(MIN(TIME(17,0,0),M38)-MAX(TIME(7,0,0),L38))*24),0) + IF(M39<>"",MAX(0,(MIN(TIME(17,0,0),M39)-MAX(TIME(7,0,0),L39))*24),0) + IF(M40<>"",MAX(0,(MIN(TIME(17,0,0),M40)-MAX(TIME(7,0,0),L40))*24),0) + IF(M41<>"",MAX(0,(MIN(TIME(17,0,0),M41)-MAX(TIME(7,0,0),L41))*24),0) + IF(M42<>"",MAX(0,(MIN(TIME(17,0,0),M42)-MAX(TIME(7,0,0),L42))*24),0) >= 7 -> TRUE | O46: =IF(P38<>"",MAX(0,(MIN(TIME(17,0,0),P38)-MAX(TIME(7,0,0),O38))*24),0) + IF(P39<>"",MAX(0,(MIN(TIME(17,0,0),P39)-MAX(TIME(7,0,0),O39))*24),0) + IF(P40<>"",MAX(0,(MIN(TIME(17,0,0),P40)-MAX(TIME(7,0,0),O40))*24),0) + IF(P41<>"",MAX(0,(MIN(TIME(17,0,0),P41)-MAX(TIME(7,0,0),O41))*24),0) + IF(P42<>"",MAX(0,(MIN(TIME(17,0,0),P42)-MAX(TIME(7,0,0),O42))*24),0) >= 7 -> TRUE | R46: =IF(S38<>"",MAX(0,(MIN(TIME(17,0,0),S38)-MAX(TIME(7,0,0),R38))*24),0) + IF(S39<>"",MAX(0,(MIN(TIME(17,0,0),S39)-MAX(TIME(7,0,0),R39))*24),0) + IF(S40<>"",MAX(0,(MIN(TIME(17,0,0),S40)-MAX(TIME(7,0,0),R40))*24),0) + IF(S41<>"",MAX(0,(MIN(TIME(17,0,0),S41)-MAX(TIME(7,0,0),R41))*24),0) + IF(S42<>"",MAX(0,(MIN(TIME(17,0,0),S42)-MAX(TIME(7,0,0),R42))*24),0) >= 7 -> TRUE | U46: N/A
A48: Total Hours (Week 2) | C48: =SUM(C44:W44) -> 39
...

Sheet Dunlap, T
A1: First Name: | C1: Trudi
A2: Last Name: | C2: Dunlap
A3: Title: | C3: Executive Director and Chief Executive Officer
A4: Birthdate: | C4: March 6
A5: Id: | C5: Dunlap-Trudi
A6: Direct: | C6: 724-814-3174
A7: Ext: | C7: 275
A8: Mobile: | C8: 724-601-2198
A9: Email: | C9: tdunlap@tms.org
A10: Photo: | C10: DunlapTrudi.jpg
A11: Dept ID: | C11: executive
A12: Role: | C12: executive
A13: Reporting: | C13: N/A
A14: Description: | C14: Short Descriptions can be added to all staff or leave blank…
A16: Work Schedule
A17: Instructions: | C17: =FormTools!B1 -> 1. MARK YOUR SCHEDULE: Use dropdown menus or begin typing to select start/end times for each day's work blocks. Leave unused blocks empty. Include location designations for each work block (Office, Remote) 2. CORE HOURS REQUIREMENT: You must routinely schedule at least 7 working hours between 7:00 AM - 5:00 PM, Monday through Thursday, unless using PTO or Travel. 3. DAILY LIMIT: Maximum 10 hours per day. Note: Non-Exempt employees are limited to 40 hours per week and all employees are limited to 75 hours per pay period, unless overtime has been approved by your supervisor. Green = Compliant, Red = Non-Compliant. Form auto-calculates totals and compliance.
C20: WEEK 1 (Pay Week)
C21: Saturday | F21: Sunday | I21: Monday | L21: Tuesday | O21: Wednesday | R21: Thursday | U21: Friday
C22: Start | D22: End | E22: Location | F22: Start | G22: End | H22: Location | I22: Start | J22: End | K22: Location | L22: Start | M22: End | N22: Location | O22: Start | P22: End | Q22: Location | R22: Start | S22: End | T22: Location | U22: Start | V22: End | W22: Location
A23: Work Block 1 | I23: 0.33333333 | J23: 0.5 | K23: Remote | L23: 0.33333333 | M23: 0.5 | N23: Remote | O23: 0.33333333 | P23: 0.5 | Q23: Office | R23: 0.33333333 | S23: 0.5 | T23: Office | U23: 0.33333333 | V23: 0.625 | W23: Remote
A24: Work Block 2 | I24: 0.52083333 | J24: 0.70833333 | K24: Remote | L24: 0.52083333 | M24: 0.70833333 | N24: Remote | O24: 0.52083333 | P24: 0.70833333 | Q24: Office | R24: 0.52083333 | S24: 0.70833333 | T24: Office
A25: Work Block 3
A26: Work Block 4
A27: Work Block 5
A29: Total HRS/Day | C29: {=SUM((D23:D27-C23:C27)*24)} -> 0 | F29: {=SUM((G23:G27-F23:F27)*24)} -> 0 | I29: {=SUM((J23:J27-I23:I27)*24)} -> 8.5 | L29: {=SUM((M23:M27-L23:L27)*24)} -> 8.5 | O29: {=SUM((P23:P27-O23:O27)*24)} -> 8.5 | R29: {=SUM((S23:S27-R23:R27)*24)} -> 8.5 | U29: {=SUM((V23:V27-U23:U27)*24)} -> 7
A30: Total HRS/Day <=10? | C30: =C29<=10 -> TRUE | F30: =F29<=10 -> TRUE | I30: =I29<=10 -> TRUE | L30: =L29<=10 -> TRUE | O30: =O29<=10 -> TRUE | R30: =R29<=10 -> TRUE | U30: =U29<=10 -> TRUE
A31: Core Hours = 7 of 10? | C31: N/A | F31: N/A | I31: =IF(J23<>"",MAX(0,(MIN(TIME(17,0,0),J23)-MAX(TIME(7,0,0),I23))*24),0) + IF(J24<>"",MAX(0,(MIN(TIME(17,0,0),J24)-MAX(TIME(7,0,0),I24))*24),0) + IF(J25<>"",MAX(0,(MIN(TIME(17,0,0),J25)-MAX(TIME(7,0,0),I25))*24),0) + IF(J26<>"",MAX(0,(MIN(TIME(17,0,0),J26)-MAX(TIME(7,0,0),I26))*24),0) + IF(J27<>"",MAX(0,(MIN(TIME(17,0,0),J27)-MAX(TIME(7,0,0),I27))*24),0) >= 7 -> TRUE | L31: =IF(M23<>"",MAX(0,(MIN(TIME(17,0,0),M23)-MAX(TIME(7,0,0),L23))*24),0) + IF(M24<>"",MAX(0,(MIN(TIME(17,0,0),M24)-MAX(TIME(7,0,0),L24))*24),0) + IF(M25<>"",MAX(0,(MIN(TIME(17,0,0),M25)-MAX(TIME(7,0,0),L25))*24),0) + IF(M26<>"",MAX(0,(MIN(TIME(17,0,0),M26)-MAX(TIME(7,0,0),L26))*24),0) + IF(M27<>"",MAX(0,(MIN(TIME(17,0,0),M27)-MAX(TIME(7,0,0),L27))*24),0) >= 7 -> TRUE | O31: =IF(P23<>"",MAX(0,(MIN(TIME(17,0,0),P23)-MAX(TIME(7,0,0),O23))*24),0) + IF(P24<>"",MAX(0,(MIN(TIME(17,0,0),P24)-MAX(TIME(7,0,0),O24))*24),0) + IF(P25<>"",MAX(0,(MIN(TIME(17,0,0),P25)-MAX(TIME(7,0,0),O25))*24),0) + IF(P26<>"",MAX(0,(MIN(TIME(17,0,0),P26)-MAX(TIME(7,0,0),O26))*24),0) + IF(P27<>"",MAX(0,(MIN(TIME(17,0,0),P27)-MAX(TIME(7,0,0),O27))*24),0) >= 7 -> TRUE | R31: =IF(S23<>"",MAX(0,(MIN(TIME(17,0,0),S23)-MAX(TIME(7,0,0),R23))*24),0) + IF(S24<>"",MAX(0,(MIN(TIME(17,0,0),S24)-MAX(TIME(7,0,0),R24))*24),0) + IF(S25<>"",MAX(0,(MIN(TIME(17,0,0),S25)-MAX(TIME(7,0,0),R25))*24),0) + IF(S26<>"",MAX(0,(MIN(TIME(17,0,0),S26)-MAX(TIME(7,0,0),R26))*24),0) + IF(S27<>"",MAX(0,(MIN(TIME(17,0,0),S27)-MAX(TIME(7,0,0),R27))*24),0) >= 7 -> TRUE | U31: N/A
A33: Total Hours (Week 1) | C33: =SUM(C29:W29) -> 41
C35: WEEK 2
C36: Saturday | F36: Sunday | I36: Monday | L36: Tuesday | O36: Wednesday | R36: Thursday | U36: Friday
C37: Start | D37: End | E37: Location | F37: Start | G37: End | H37: Location | I37: Start | J37: End | K37: Location | L37: Start | M37: End | N37: Location | O37: Start | P37: End | Q37: Location | R37: Start | S37: End | T37: Location | U37: Start | V37: End | W37: Location
A38: Work Block 1 | I38: 0.33333333 | J38: 0.5 | K38: Remote | L38: 0.33333333 | M38: 0.5 | N38: Remote | O38: 0.33333333 | P38: 0.5 | Q38: Office | R38: 0.33333333 | S38: 0.5 | T38: Office
A39: Work Block 2 | I39: 0.52083333 | J39: 0.70833333 | K39: Remote | L39: 0.52083333 | M39: 0.70833333 | N39: Remote | O39: 0.52083333 | P39: 0.70833333 | Q39: Office | R39: 0.52083333 | S39: 0.70833333 | T39: Office
A40: Work Block 3
A41: Work Block 4
A42: Work Block 5
A44: Total HRS/Day | C44: {=SUM((D38:D42-C38:C42)*24)} -> 0 | F44: {=SUM((G38:G42-F38:F42)*24)} -> 0 | I44: {=SUM((J38:J42-I38:I42)*24)} -> 8.5 | L44: {=SUM((M38:M42-L38:L42)*24)} -> 8.5 | O44: {=SUM((P38:P42-O38:O42)*24)} -> 8.5 | R44: {=SUM((S38:S42-R38:R42)*24)} -> 8.5 | U44: {=SUM((V38:V42-U38:U42)*24)} -> 0
A45: Total HRS/Day <=10? | C45: =C44<=10 -> TRUE | F45: =F44<=10 -> TRUE | I45: =I44<=10 -> TRUE | L45: =L44<=10 -> TRUE | O45: =O44<=10 -> TRUE | R45: =R44<=10 -> TRUE | U45: =U44<=10 -> TRUE
A46: Core Hours = 7 of 10? | C46: N/A | F46: N/A | I46: =IF(J38<>"",MAX(0,(MIN(TIME(17,0,0),J38)-MAX(TIME(7,0,0),I38))*24),0) + IF(J39<>"",MAX(0,(MIN(TIME(17,0,0),J39)-MAX(TIME(7,0,0),I39))*24),0) + IF(J40<>"",MAX(0,(MIN(TIME(17,0,0),J40)-MAX(TIME(7,0,0),I40))*24),0) + IF(J41<>"",MAX(0,(MIN(TIME(17,0,0),J41)-MAX(TIME(7,0,0),I41))*24),0) + IF(J42<>"",MAX(0,(MIN(TIME(17,0,0),J42)-MAX(TIME(7,0,0),I42))*24),0) >= 7 -> TRUE | L46: =IF(M38<>"",MAX(0,(MIN(TIME(17,0,0),M38)-MAX(TIME(7,0,0),L38))*24),0) + IF(M39<>"",MAX(0,(MIN(TIME(17,0,0),M39)-MAX(TIME(7,0,0),L39))*24),0) + IF(M40<>"",MAX(0,(MIN(TIME(17,0,0),M40)-MAX(TIME(7,0,0),L40))*24),0) + IF(M41<>"",MAX(0,(MIN(TIME(17,0,0),M41)-MAX(TIME(7,0,0),L41))*24),0) + IF(M42<>"",MAX(0,(MIN(TIME(17,0,0),M42)-MAX(TIME(7,0,0),L42))*24),0) >= 7 -> TRUE | O46: =IF(P38<>"",MAX(0,(MIN(TIME(17,0,0),P38)-MAX(TIME(7,0,0),O38))*24),0) + IF(P39<>"",MAX(0,(MIN(TIME(17,0,0),P39)-MAX(TIME(7,0,0),O39))*24),0) + IF(P40<>"",MAX(0,(MIN(TIME(17,0,0),P40)-MAX(TIME(7,0,0),O40))*24),0) + IF(P41<>"",MAX(0,(MIN(TIME(17,0,0),P41)-MAX(TIME(7,0,0),O41))*24),0) + IF(P42<>"",MAX(0,(MIN(TIME(17,0,0),P42)-MAX(TIME(7,0,0),O42))*24),0) >= 7 -> TRUE | R46: =IF(S38<>"",MAX(0,(MIN(TIME(17,0,0),S38)-MAX(TIME(7,0,0),R38))*24),0) + IF(S39<>"",MAX(0,(MIN(TIME(17,0,0),S39)-MAX(TIME(7,0,0),R39))*24),0) + IF(S40<>"",MAX(0,(MIN(TIME(17,0,0),S40)-MAX(TIME(7,0,0),R40))*24),0) + IF(S41<>"",MAX(0,(MIN(TIME(17,0,0),S41)-MAX(TIME(7,0,0),R41))*24),0) + IF(S42<>"",MAX(0,(MIN(TIME(17,0,0),S42)-MAX(TIME(7,0,0),R42))*24),0) >= 7 -> TRUE | U46: N/A
A48: Total Hours (Week 2) | C48: =SUM(C44:W44) -> 34
...

Sheet Enright, M
A1: First Name: | C1: Megan
A2: Last Name: | C2: Enright
A3: Title: | C3: Marketing Administrator
A4: Birthdate: | C4: October 8
A5: Id: | C5: Enright-Megan
A6: Direct: | C6: 724-814-3106
A7: Ext: | C7: 243
A8: Mobile: | C8: 860-681-9485
A9: Email: | C9: menright@tms.org
A10: Photo: | C10: EnrightMegan.jpg
A11: Dept ID: | C11: marketing
A12: Role: | C12: manager
A13: Reporting: | C13: Bohnert-Ashley
A14: Description: | C14: Short Descriptions can be added to all staff or leave blank…
A16: Work Schedule
A17: Instructions: | C17: =FormTools!B1 -> 1. MARK YOUR SCHEDULE: Use dropdown menus or begin typing to select start/end times for each day's work blocks. Leave unused blocks empty. Include location designations for each work block (Office, Remote) 2. CORE HOURS REQUIREMENT: You must routinely schedule at least 7 working hours between 7:00 AM - 5:00 PM, Monday through Thursday, unless using PTO or Travel. 3. DAILY LIMIT: Maximum 10 hours per day. Note: Non-Exempt employees are limited to 40 hours per week and all employees are limited to 75 hours per pay period, unless overtime has been approved by your supervisor. Green = Compliant, Red = Non-Compliant. Form auto-calculates totals and compliance.
C20: WEEK 1 (Pay Week)
C21: Saturday | F21: Sunday | I21: Monday | L21: Tuesday | O21: Wednesday | R21: Thursday | U21: Friday
C22: Start | D22: End | E22: Location | F22: Start | G22: End | H22: Location | I22: Start | J22: End | K22: Location | L22: Start | M22: End | N22: Location | O22: Start | P22: End | Q22: Location | R22: Start | S22: End | T22: Location | U22: Start | V22: End | W22: Location
A23: Work Block 1 | I23: 0.33333333 | J23: 0.6875 | K23: Remote | L23: 0.33333333 | M23: 0.6875 | N23: Remote | O23: 0.33333333 | P23: 0.6875 | Q23: Remote | R23: 0.33333333 | S23: 0.6875 | T23: Remote
A24: Work Block 2
A25: Work Block 3
A26: Work Block 4
A27: Work Block 5
A29: Total HRS/Day | C29: {=SUM((D23:D27-C23:C27)*24)} -> 0 | F29: {=SUM((G23:G27-F23:F27)*24)} -> 0 | I29: {=SUM((J23:J27-I23:I27)*24)} -> 8.5 | L29: {=SUM((M23:M27-L23:L27)*24)} -> 8.5 | O29: {=SUM((P23:P27-O23:O27)*24)} -> 8.5 | R29: {=SUM((S23:S27-R23:R27)*24)} -> 8.5 | U29: {=SUM((V23:V27-U23:U27)*24)} -> 0
A30: Total HRS/Day <=10? | C30: =C29<=10 -> TRUE | F30: =F29<=10 -> TRUE | I30: =I29<=10 -> TRUE | L30: =L29<=10 -> TRUE | O30: =O29<=10 -> TRUE | R30: =R29<=10 -> TRUE | U30: =U29<=10 -> TRUE
A31: Core Hours = 7 of 10? | C31: N/A | F31: N/A | I31: =IF(J23<>"",MAX(0,(MIN(TIME(17,0,0),J23)-MAX(TIME(7,0,0),I23))*24),0) + IF(J24<>"",MAX(0,(MIN(TIME(17,0,0),J24)-MAX(TIME(7,0,0),I24))*24),0) + IF(J25<>"",MAX(0,(MIN(TIME(17,0,0),J25)-MAX(TIME(7,0,0),I25))*24),0) + IF(J26<>"",MAX(0,(MIN(TIME(17,0,0),J26)-MAX(TIME(7,0,0),I26))*24),0) + IF(J27<>"",MAX(0,(MIN(TIME(17,0,0),J27)-MAX(TIME(7,0,0),I27))*24),0) >= 7 -> TRUE | L31: =IF(M23<>"",MAX(0,(MIN(TIME(17,0,0),M23)-MAX(TIME(7,0,0),L23))*24),0) + IF(M24<>"",MAX(0,(MIN(TIME(17,0,0),M24)-MAX(TIME(7,0,0),L24))*24),0) + IF(M25<>"",MAX(0,(MIN(TIME(17,0,0),M25)-MAX(TIME(7,0,0),L25))*24),0) + IF(M26<>"",MAX(0,(MIN(TIME(17,0,0),M26)-MAX(TIME(7,0,0),L26))*24),0) + IF(M27<>"",MAX(0,(MIN(TIME(17,0,0),M27)-MAX(TIME(7,0,0),L27))*24),0) >= 7 -> TRUE | O31: =IF(P23<>"",MAX(0,(MIN(TIME(17,0,0),P23)-MAX(TIME(7,0,0),O23))*24),0) + IF(P24<>"",MAX(0,(MIN(TIME(17,0,0),P24)-MAX(TIME(7,0,0),O24))*24),0) + IF(P25<>"",MAX(0,(MIN(TIME(17,0,0),P25)-MAX(TIME(7,0,0),O25))*24),0) + IF(P26<>"",MAX(0,(MIN(TIME(17,0,0),P26)-MAX(TIME(7,0,0),O26))*24),0) + IF(P27<>"",MAX(0,(MIN(TIME(17,0,0),P27)-MAX(TIME(7,0,0),O27))*24),0) >= 7 -> TRUE | R31: =IF(S23<>"",MAX(0,(MIN(TIME(17,0,0),S23)-MAX(TIME(7,0,0),R23))*24),0) + IF(S24<>"",MAX(0,(MIN(TIME(17,0,0),S24)-MAX(TIME(7,0,0),R24))*24),0) + IF(S25<>"",MAX(0,(MIN(TIME(17,0,0),S25)-MAX(TIME(7,0,0),R25))*24),0) + IF(S26<>"",MAX(0,(MIN(TIME(17,0,0),S26)-MAX(TIME(7,0,0),R26))*24),0) + IF(S27<>"",MAX(0,(MIN(TIME(17,0,0),S27)-MAX(TIME(7,0,0),R27))*24),0) >= 7 -> TRUE | U31: N/A
A33: Total Hours (Week 1) | C33: =SUM(C29:W29) -> 34
C35: WEEK 2
C36: Saturday | F36: Sunday | I36: Monday | L36: Tuesday | O36: Wednesday | R36: Thursday | U36: Friday
C37: Start | D37: End | E37: Location | F37: Start | G37: End | H37: Location | I37: Start | J37: End | K37: Location | L37: Start | M37: End | N37: Location | O37: Start | P37: End | Q37: Location | R37: Start | S37: End | T37: Location | U37: Start | V37: End | W37: Location
A38: Work Block 1 | I38: 0.33333333 | J38: 0.6875 | K38: Remote | L38: 0.33333333 | M38: 0.6875 | N38: Remote | O38: 0.33333333 | P38: 0.6875 | Q38: Remote | R38: 0.33333333 | S38: 0.6875 | T38: Remote | U38: 0.33333333 | V38: 0.625 | W38: Remote
A39: Work Block 2
A40: Work Block 3
A41: Work Block 4
A42: Work Block 5
A44: Total HRS/Day | C44: {=SUM((D38:D42-C38:C42)*24)} -> 0 | F44: {=SUM((G38:G42-F38:F42)*24)} -> 0 | I44: {=SUM((J38:J42-I38:I42)*24)} -> 8.5 | L44: {=SUM((M38:M42-L38:L42)*24)} -> 8.5 | O44: {=SUM((P38:P42-O38:O42)*24)} -> 8.5 | R44: {=SUM((S38:S42-R38:R42)*24)} -> 8.5 | U44: {=SUM((V38:V42-U38:U42)*24)} -> 7
A45: Total HRS/Day <=10? | C45: =C44<=10 -> TRUE | F45: =F44<=10 -> TRUE | I45: =I44<=10 -> TRUE | L45: =L44<=10 -> TRUE | O45: =O44<=10 -> TRUE | R45: =R44<=10 -> TRUE | U45: =U44<=10 -> TRUE
A46: Core Hours = 7 of 10? | C46: N/A | F46: N/A | I46: =IF(J38<>"",MAX(0,(MIN(TIME(17,0,0),J38)-MAX(TIME(7,0,0),I38))*24),0) + IF(J39<>"",MAX(0,(MIN(TIME(17,0,0),J39)-MAX(TIME(7,0,0),I39))*24),0) + IF(J40<>"",MAX(0,(MIN(TIME(17,0,0),J40)-MAX(TIME(7,0,0),I40))*24),0) + IF(J41<>"",MAX(0,(MIN(TIME(17,0,0),J41)-MAX(TIME(7,0,0),I41))*24),0) + IF(J42<>"",MAX(0,(MIN(TIME(17,0,0),J42)-MAX(TIME(7,0,0),I42))*24),0) >= 7 -> TRUE | L46: =IF(M38<>"",MAX(0,(MIN(TIME(17,0,0),M38)-MAX(TIME(7,0,0),L38))*24),0) + IF(M39<>"",MAX(0,(MIN(TIME(17,0,0),M39)-MAX(TIME(7,0,0),L39))*24),0) + IF(M40<>"",MAX(0,(MIN(TIME(17,0,0),M40)-MAX(TIME(7,0,0),L40))*24),0) + IF(M41<>"",MAX(0,(MIN(TIME(17,0,0),M41)-MAX(TIME(7,0,0),L41))*24),0) + IF(M42<>"",MAX(0,(MIN(TIME(17,0,0),M42)-MAX(TIME(7,0,0),L42))*24),0) >= 7 -> TRUE | O46: =IF(P38<>"",MAX(0,(MIN(TIME(17,0,0),P38)-MAX(TIME(7,0,0),O38))*24),0) + IF(P39<>"",MAX(0,(MIN(TIME(17,0,0),P39)-MAX(TIME(7,0,0),O39))*24),0) + IF(P40<>"",MAX(0,(MIN(TIME(17,0,0),P40)-MAX(TIME(7,0,0),O40))*24),0) + IF(P41<>"",MAX(0,(MIN(TIME(17,0,0),P41)-MAX(TIME(7,0,0),O41))*24),0) + IF(P42<>"",MAX(0,(MIN(TIME(17,0,0),P42)-MAX(TIME(7,0,0),O42))*24),0) >= 7 -> TRUE | R46: =IF(S38<>"",MAX(0,(MIN(TIME(17,0,0),S38)-MAX(TIME(7,0,0),R38))*24),0) + IF(S39<>"",MAX(0,(MIN(TIME(17,0,0),S39)-MAX(TIME(7,0,0),R39))*24),0) + IF(S40<>"",MAX(0,(MIN(TIME(17,0,0),S40)-MAX(TIME(7,0,0),R40))*24),0) + IF(S41<>"",MAX(0,(MIN(TIME(17,0,0),S41)-MAX(TIME(7,0,0),R41))*24),0) + IF(S42<>"",MAX(0,(MIN(TIME(17,0,0),S42)-MAX(TIME(7,0,0),R42))*24),0) >= 7 -> TRUE | U46: N/A
A48: Total Hours (Week 2) | C48: =SUM(C44:W44) -> 41
...

Sheet Geier, C
A1: First Name: | C1: Cheryl
A2: Last Name: | C2: Geier
A3: Title: | C3: Senior Graphic Designer
A4: Birthdate: | C4: March 12
A5: Id: | C5: Geier-Cheryl
A6: Direct: | C6: 724-814-3154
A7: Ext: | C7: 240
A8: Mobile: | C8: 724-316-8775
A9: Email: | C9: cgeier@tms.org
A10: Photo: | C10: GeierCheryl.jpg
A11: Dept ID: | C11: marketing
A12: Role: | C12: staff
A13: Reporting: | C13: Rasel-Dave
A14: Description: | C14: Short Descriptions can be added to all staff or leave blank…
A16: Work Schedule
A17: Instructions: | C17: =FormTools!B1 -> 1. MARK YOUR SCHEDULE: Use dropdown menus or begin typing to select start/end times for each day's work blocks. Leave unused blocks empty. Include location designations for each work block (Office, Remote) 2. CORE HOURS REQUIREMENT: You must routinely schedule at least 7 working hours between 7:00 AM - 5:00 PM, Monday through Thursday, unless using PTO or Travel. 3. DAILY LIMIT: Maximum 10 hours per day. Note: Non-Exempt employees are limited to 40 hours per week and all employees are limited to 75 hours per pay period, unless overtime has been approved by your supervisor. Green = Compliant, Red = Non-Compliant. Form auto-calculates totals and compliance.
C20: WEEK 1 (Pay Week)
C21: Saturday | F21: Sunday | I21: Monday | L21: Tuesday | O21: Wednesday | R21: Thursday | U21: Friday
C22: Start | D22: End | E22: Location | F22: Start | G22: End | H22: Location | I22: Start | J22: End | K22: Location | L22: Start | M22: End | N22: Location | O22: Start | P22: End | Q22: Location | R22: Start | S22: End | T22: Location | U22: Start | V22: End | W22: Location
A23: Work Block 1 | I23: 0.5 | J23: 0.625 | K23: Remote | L23: 0.41666667 | M23: 0.5625 | N23: Remote | O23: 0.41666667 | P23: 0.5625 | Q23: Remote | R23: 0.5 | S23: 0.625 | T23: Remote | U23: 0.41666667 | V23: 0.5 | W23: Remote
A24: Work Block 2
A25: Work Block 3
A26: Work Block 4
A27: Work Block 5
A29: Total HRS/Day | C29: {=SUM((D23:D27-C23:C27)*24)} -> 0 | F29: {=SUM((G23:G27-F23:F27)*24)} -> 0 | I29: {=SUM((J23:J27-I23:I27)*24)} -> 3 | L29: {=SUM((M23:M27-L23:L27)*24)} -> 3.5 | O29: {=SUM((P23:P27-O23:O27)*24)} -> 3.5 | R29: {=SUM((S23:S27-R23:R27)*24)} -> 3 | U29: {=SUM((V23:V27-U23:U27)*24)} -> 2
